Workbook
Name _01_: Approvers!$J$3:$J$19
Name AM110000_: Approvers!$J$20:$J$21
Name COSTCENTER: Approvers!$C$2:$C$208
Name CP110000_: Approvers!$J$22:$J$24
Name CT110000_: Approvers!$J$25:$J$27
Name DEPARTMENT: Approvers!$B$2:$B$109
Name DIVISION: Approvers!$A$2:$A$28
Name GM110000_: Approvers!$J$28:$J$33
Name GM210000_: Approvers!$J$34:$J$36
Name GM410000_: Approvers!$J$37:$J$39
Name GM510000_: Approvers!$J$40:$J$48
Name GM610000_: Approvers!$J$49:$J$49
Name GM710000_: Approvers!$J$50:$J$53
Name GM810000_: Approvers!$J$54:$J$56
Name GM910000_: Approvers!$J$57:$J$60
Name HS110000_: Approvers!$J$61:$J$84
Name HS210000_: Approvers!$J$85:$J$131
Name HS310000_: Approvers!$J$132:$J$134
Name HS810000_: Approvers!$J$135:$J$142
Name IA110000_: Approvers!$J$143
Name MULTI___BU: Approvers!$J$2
Name SH110000_: Approvers!$J$144:$J$159
Name SH110001_: Approvers!$J$157:$J$159
Name SH112000_: Approvers!$J$160:$J$161
Name SH113000_: Approvers!$J$162:$J$164
Name SH210000_: Approvers!$J$165:$J$169
Name SH310000_: Approvers!$J$170:$J$171
Name SH410000_: Approvers!$J$172:$J$189
Name SH510000_: Approvers!$J$190:$J$198
Name SH810000_: Approvers!$J$199:$J$203
Name SH910000_: Approvers!$J$204:$J$207

Sheet Dynamics Enum Cache

Sheet Bid Tab (F&B Ops and CatMan) 10
G2: BID TABULATION TEMPLATE - DETAILED | L2: SUPPLIER TYPE | M2: PROCUREMENT METHOD | O2: AWARD METHOD | AV2: Document Code | AX2: SCD-PSP-PRT-FO-004
G3: BID CATEGORY: | AV3: Revision Number | AX3: 06
G4: REQUESTING DIVISION: | AV4: Effective Date | AX4: 45474
G5: COST CENTER / NAME:
G6: SRF REFERENCE #: | AJ6: PRICE COMPARISON
G7: RINGI REFERENCE #: | AJ7: BIDDERS
AJ8: 1 | AP8: 2 | AV8: 3 | BB8: 4 | BH8: 5 | BN8: 6
A9: # | B9: REDROCK ITEM CODE <Input "NEW" for New Items> | C9: ITEM NAME AND DESCRIPTION | D9: ESTIMATED QTY | E9: UOM | F9: BASELINE- CURRENT | J9: MARKET PRICING | M9: RECOMMENDED AWARD | P9: BID ANALYSIS | AB9: PROCUREMENT SAVINGS | AG9: PRICE DIFF VS CURRENT SPEND | AJ9: VENDOR 1 | AP9: VENDOR 2 | AV9: VENDOR 3 | BB9: VENDOR 4 | BH9: VENDOR 5 | BN9: VENDOR 6 | BT9: VENDOR 7 | BZ9: VENDOR 8 | CF9: VENDOR 9 | CL9: VENDOR 10
D10: +/- 10-15% Variance | F10: SUPPLIER | G10: LAST SYSTEM PRICE | H10: LAST SYSTEM UPLOAD DATE | I10: EXTENDED COST | J10: SRP | K10: REFERENCE | L10: DIFF % SRP | M10: SUPPLIER | N10: UNIT COST | O10: EXTENDED COST | P10: INITIAL LOWEST COMPLIANT BID | Q10: VENDOR CHECK - CURRENT | R10: # OF BIDDERS | S10: AWARDED TO LOWEST | T10: AVE. BID | U10: AVE. BID % VS SYSTEM PRICE | V10: AWARDED TO LOWEST COMPLIANT | W10: LOWEST COMPLIANT VENDOR | X10: RECOMMENDED AMOUNT | Y10: AWARDED TO RECOMMENDED | Z10: LOWEST COMPLIANT BID | AA10: TOTAL LOWEST COMPLIANT / RECOMMENDED BID | AB10: UNIT COST SAVINGS REFERENCE | AC10: GROSS AMOUNT | AD10: UNIT SAVINGS | AE10: TOTAL SAVINGS | AF10: PRICE BENCHMARK | AG10: UNIT PRICE DIFF CURRENT | AH10: EXTENDED PRICE DIFF CURRENT | AI10: PRICE DIFF % CURRENT | AJ10: Initial Bid | AK10: Negotiated Bid | AL10: Extended Cost | AM10: % Variance from System Price | AN10: Remarks | AO10: Compliant | AP10: Initial Bid | AQ10: Negotiated Bid | AR10: Extended Cost | AS10: % Variance from System Price | AT10: Remarks | AU10: Compliant | AV10: Initial Bid | AW10: Negotiated Bid | AX10: Extended Cost | AY10: % Variance from System Price | AZ10: Remarks | BA10: Compliant | BB10: Initial Bid | BC10: Negotiated Bid | BD10: Extended Cost | BE10: % Variance from System Price | BF10: Remarks | BG10: Compliant | BH10: Initial Bid | BI10: Negotiated Bid | BJ10: Extended Cost | BK10: % Variance from System Price | BL10: Remarks | BM10: Compliant | BN10: Initial Bid | BO10: Negotiated Bid | BP10: Extended Cost | BQ10: % Variance from System Price | BR10: Remarks | BS10: Compliant | BT10: Initial Bid | BU10: Negotiated Bid | BV10: Extended Cost | BW10: % Variance from System Price | BX10: Remarks | BY10: Compliant | BZ10: Initial Bid | CA10: Negotiated Bid | CB10: Extended Cost | CC10: % Variance from System Price | CD10: Remarks | CE10: Compliant | CF10: Initial Bid | CG10: Negotiated Bid | CH10: Extended Cost | CI10: % Variance from System Price | CJ10: Remarks | CK10: Compliant | CL10: Initial Bid | CM10: Negotiated Bid | CN10: Extended Cost | CO10: % Variance from System Price | CP10: Remarks | CQ10: Compliant
A11: 1 | I11: =G11*D11 -> 0 | L11: =IFERROR((J11-N11)/J11,0) -> 0 | M11: =IF(N11>0,IF(N11=AK11,$AJ$9,IF(N11=AQ11,$AP$9,IF(N11=AW11,$AV$9,IF(N11=BC11,$BB$9,IF(N11=BI11,$BH$9,IF(N11=BO11,$BN$9,IF(N11=BU11,$BT$9,IF(N11=CA11,$BZ$9,IF(N11=CG11,$CF$9,IF(N11=CM11,$CL$9,"")))))))))),"") | N11: =IF(X11>0,X11,Z11) -> 0 | O11: =IFERROR(N11*D11,"") -> 0 | P11: =MIN(IF($AO11=Reference!$A$10,100000000,AJ11),IF($AU11=Reference!$A$10,100000000,AP11),IF($BA11=Reference!$A$10,100000000,AV11),IF($BG11=Reference!$A$10,100000000,BB11),IF($BM11=Reference!$A$10,100000000,BH11),IF($BS11=Reference!$A$10,100000000,BN11),IF($BY11=Reference!$A$10,100000000,BT11),IF($CE11=Reference!$A$10,100000000,BZ11),IF($CK11=Reference!$A$10,100000000,CF11),IF($CQ11=Reference!$A$10,100000000,CL11)) -> 0 | Q11: =W11=F11 -> FALSE | R11: =COUNT(BC11,AK11,AQ11,AW11,BI11,BO11,BU11,CA11,CG11,CM11) -> 0 | S11: =MIN(AK11,AQ11,AW11,BC11,BI11,BO11,BU11,CA11,CG11,CM11)=N11 -> TRUE | T11: =IFERROR(AVERAGE(AK11,AQ11,AW11,BC11,BI11,BO11,BU11,CA11,CG11,CM11),"") | U11: =IFERROR(((G11-T11)/G11),"") | V11: =$Z11=$N11 -> TRUE | W11: =IF(Z11=AK11,$AJ$9,IF(Z11=AQ11,$AP$9,IF(Z11=AW11,$AV$9,IF(Z11=BC11,$BB$9,IF(Z11=BI11,$BH$9,IF(Z11=BO11,$BN$9,IF(Z11=BU11,$BT$9,IF(Z11=CA11,$BZ$9,IF(Z11=CG11,$CF$9,IF(Z11=CM11,$CL$9)))))))))) -> VENDOR 1 | X11: =IF(AO11=Reference!$A$8,'Bid Tab (F&B Ops and CatMan) 10'!AK11,IF('Bid Tab (F&B Ops and CatMan) 10'!AU11=Reference!$A$8,'Bid Tab (F&B Ops and CatMan) 10'!AQ11,IF('Bid Tab (F&B Ops and CatMan) 10'!BA11=Reference!$A$8,'Bid Tab (F&B Ops and CatMan) 10'!AW11,IF('Bid Tab (F&B Ops and CatMan) 10'!BG11=Reference!$A$8,'Bid Tab (F&B Ops and CatMan) 10'!BC11,IF('Bid Tab (F&B Ops and CatMan) 10'!BM11=Reference!$A$8,'Bid Tab (F&B Ops and CatMan) 10'!BI11,IF('Bid Tab (F&B Ops and CatMan) 10'!BS11=Reference!$A$8,'Bid Tab (F&B Ops and CatMan) 10'!BO11,IF('Bid Tab (F&B Ops and CatMan) 10'!BY11=Reference!$A$8,'Bid Tab (F&B Ops and CatMan) 10'!BU11,IF('Bid Tab (F&B Ops and CatMan) 10'!CE11=Reference!$A$8,'Bid Tab (F&B Ops and CatMan) 10'!CA11,IF('Bid Tab (F&B Ops and CatMan) 10'!CK11=Reference!$A$8,'Bid Tab (F&B Ops and CatMan) 10'!CG11,IF('Bid Tab (F&B Ops and CatMan) 10'!CQ11=Reference!$A$8,'Bid Tab (F&B Ops and CatMan) 10'!CM11,0)))))))))) -> 0 | Y11: =IFERROR(IF(Reference!$A$8=HLOOKUP(Reference!$A$8,'Bid Tab (F&B Ops and CatMan) 10'!AJ11:CQ11,1,0),TRUE,FALSE),FALSE) -> FALSE | Z11: =MIN(IF(AO11=Reference!$A$10,100000000,AK11),IF(AU11=Reference!$A$10,100000000,AQ11),IF(BA11=Reference!$A$10,100000000,AW11),IF(BG11=Reference!$A$10,100000000,BC11),IF(BM11=Reference!$A$10,100000000,BI11),IF(BS11=Reference!$A$10,100000000,BO11),IF(BY11=Reference!$A$10,100000000,BU11),IF(CE11=Reference!$A$10,100000000,CA11),IF(CK11=Reference!$A$10,100000000,CG11),IF(CQ11=Reference!$A$10,100000000,CM11)) -> 0 | AA11: =IF(X11>0,X11*D11,Z11*D11) -> 0 | AB11: =IF(Reference!A18>0,Reference!A18,MAX(IF(TODAY()-H11<365,IF(G11>=N11,G11,P11),P11),G11)) -> 0 | AC11: =IF(AE11>0,AB11*$D11,O11) -> 0 | AD11: =IF(N11>$AB11,0,(($AB11-N11))) -> 0 | AE11: =IF(N11>$AB11,0,(($AB11-N11)*$D11)) -> 0 | AF11: =IF(AND((AD11=0),(F11=M11),(G11=N11),(TODAY()-H11<365)),"PRICE EXTENSION",IF(AND(G11=AB11,G11>0),"LAST SYSTEM PRICE",IF(AB11>0,"INITIAL LOWEST BID"," "))) | AG11: =IF(G11>0,G11-Z11,0) -> 0 | AH11: =AG11*D11 -> 0 | AI11: =IFERROR((G11-Z11)/G11,0) -> 0 | AL11: =IFERROR(AK11*$D11,0) -> 0 | AM11: =IFERROR(($G11-AK11)/$G11,0) -> 0 | AR11: =IFERROR(AQ11*$D11,0) -> 0 | AS11: =IFERROR(($G11-AQ11)/$G11,0) -> 0 | AX11: =IFERROR(AW11*$D11,0) -> 0 | AY11: =IFERROR(($G11-AW11)/$G11,0) -> 0 | BD11: N | BE11: =IFERROR(($G11-BC11)/$G11,0) -> 0 | BJ11: =IFERROR(BI11*$D11,0) -> 0 | BK11: =IFERROR(($G11-BI11)/$G11,0) -> 0 | BP11: =IFERROR(BO11*$D11,0) -> 0 | BQ11: =IFERROR(($G11-BO11)/$G11,0) -> 0 | BV11: =IFERROR(BU11*$D11,0) -> 0 | BW11: =IFERROR(($G11-BU11)/$G11,0) -> 0 | CB11: =IFERROR(CA11*$D11,0) -> 0 | CC11: =IFERROR(($G11-CA11)/$G11,0) -> 0 | CH11: =IFERROR(CG11*$D11,0) -> 0 | CI11: =IFERROR(($G11-CG11)/$G11,0) -> 0 | CN11: =IFERROR(CM11*$D11,0) -> 0 | CO11: =IFERROR(($G11-CM11)/$G11,0) -> 0
A12: 2 | I12: =G12*D12 -> 0 | L12: =IFERROR((J12-N12)/J12,0) -> 0 | M12: =IF(N12>0,IF(N12=AK12,$AJ$9,IF(N12=AQ12,$AP$9,IF(N12=AW12,$AV$9,IF(N12=BC12,$BB$9,IF(N12=BI12,$BH$9,IF(N12=BO12,$BN$9,IF(N12=BU12,$BT$9,IF(N12=CA12,$BZ$9,IF(N12=CG12,$CF$9,IF(N12=CM12,$CL$9,"")))))))))),"") | N12: =IF(X12>0,X12,Z12) -> 0 | O12: =IFERROR(N12*D12,"") -> 0 | P12: =MIN(IF($AO12=Reference!$A$10,100000000,AJ12),IF($AU12=Reference!$A$10,100000000,AP12),IF($BA12=Reference!$A$10,100000000,AV12),IF($BG12=Reference!$A$10,100000000,BB12),IF($BM12=Reference!$A$10,100000000,BH12),IF($BS12=Reference!$A$10,100000000,BN12),IF($BY12=Reference!$A$10,100000000,BT12),IF($CE12=Reference!$A$10,100000000,BZ12),IF($CK12=Reference!$A$10,100000000,CF12),IF($CQ12=Reference!$A$10,100000000,CL12)) -> 0 | Q12: =W12=F12 -> FALSE | R12: =COUNT(BC12,AK12,AQ12,AW12,BI12,BO12,BU12,CA12,CG12,CM12) -> 0 | S12: =MIN(AK12,AQ12,AW12,BC12,BI12,BO12,BU12,CA12,CG12,CM12)=N12 -> TRUE | T12: =IFERROR(AVERAGE(AK12,AQ12,AW12,BC12,BI12,BO12,BU12,CA12,CG12,CM12),"") | U12: =IFERROR(((G12-T12)/G12),"") | V12: =$Z12=$N12 -> TRUE | W12: =IF(Z12=AK12,$AJ$9,IF(Z12=AQ12,$AP$9,IF(Z12=AW12,$AV$9,IF(Z12=BC12,$BB$9,IF(Z12=BI12,$BH$9,IF(Z12=BO12,$BN$9,IF(Z12=BU12,$BT$9,IF(Z12=CA12,$BZ$9,IF(Z12=CG12,$CF$9,IF(Z12=CM12,$CL$9,"")))))))))) -> VENDOR 1 | X12: =IF(AO12=Reference!$A$8,'Bid Tab (F&B Ops and CatMan) 10'!AK12,IF('Bid Tab (F&B Ops and CatMan) 10'!AU12=Reference!$A$8,'Bid Tab (F&B Ops and CatMan) 10'!AQ12,IF('Bid Tab (F&B Ops and CatMan) 10'!BA12=Reference!$A$8,'Bid Tab (F&B Ops and CatMan) 10'!AW12,IF('Bid Tab (F&B Ops and CatMan) 10'!BG12=Reference!$A$8,'Bid Tab (F&B Ops and CatMan) 10'!BC12,IF('Bid Tab (F&B Ops and CatMan) 10'!BM12=Reference!$A$8,'Bid Tab (F&B Ops and CatMan) 10'!BI12,IF('Bid Tab (F&B Ops and CatMan) 10'!BS12=Reference!$A$8,'Bid Tab (F&B Ops and CatMan) 10'!BO12,IF('Bid Tab (F&B Ops and CatMan) 10'!BY12=Reference!$A$8,'Bid Tab (F&B Ops and CatMan) 10'!BU12,IF('Bid Tab (F&B Ops and CatMan) 10'!CE12=Reference!$A$8,'Bid Tab (F&B Ops and CatMan) 10'!CA12,IF('Bid Tab (F&B Ops and CatMan) 10'!CK12=Reference!$A$8,'Bid Tab (F&B Ops and CatMan) 10'!CG12,IF('Bid Tab (F&B Ops and CatMan) 10'!CQ12=Reference!$A$8,'Bid Tab (F&B Ops and CatMan) 10'!CM12,0)))))))))) -> 0 | Y12: =IFERROR(IF(Reference!$A$8=HLOOKUP(Reference!$A$8,'Bid Tab (F&B Ops and CatMan) 10'!AJ12:CQ12,1,0),TRUE,FALSE),FALSE) -> FALSE | Z12: =MIN(IF(AO12=Reference!$A$10,100000000,AK12),IF(AU12=Reference!$A$10,100000000,AQ12),IF(BA12=Reference!$A$10,100000000,AW12),IF(BG12=Reference!$A$10,100000000,BC12),IF(BM12=Reference!$A$10,100000000,BI12),IF(BS12=Reference!$A$10,100000000,BO12),IF(BY12=Reference!$A$10,100000000,BU12),IF(CE12=Reference!$A$10,100000000,CA12),IF(CK12=Reference!$A$10,100000000,CG12),IF(CQ12=Reference!$A$10,100000000,CM12)) -> 0 | AA12: =IF(X12>0,X12*D12,Z12*D12) -> 0 | AB12: =IF(Reference!A19>0,Reference!A19,MAX(IF(TODAY()-H12<365,IF(G12>=N12,G12,P12),P12),G12)) -> 0 | AC12: =IF(AE12>0,AB12*$D12,O12) -> 0 | AD12: =IF(N12>$AB12,0,(($AB12-N12))) -> 0 | AE12: =IF(N12>$AB12,0,(($AB12-N12)*$D12)) -> 0 | AF12: =IF(AND((AD12=0),(F12=M12),(G12=N12),(TODAY()-H12<365)),"PRICE EXTENSION",IF(AND(G12=AB12,G12>0),"LAST SYSTEM PRICE",IF(AB12>0,"INITIAL LOWEST BID"," "))) | AG12: =IF(G12>0,G12-Z12,0) -> 0 | AH12: =AG12*D12 -> 0 | AI12: =IFERROR((G12-Z12)/G12,0) -> 0 | AL12: =IFERROR(AK12*$D12,0) -> 0 | AM12: =IFERROR(($G12-AK12)/$G12,0) -> 0 | AR12: =IFERROR(AQ12*$D12,0) -> 0 | AS12: =IFERROR(($G12-AQ12)/$G12,0) -> 0 | AX12: =IFERROR(AW12*$D12,0) -> 0 | AY12: =IFERROR(($G12-AW12)/$G12,0) -> 0 | BD12: =IFERROR(BC12*$D12,0) -> 0 | BE12: =IFERROR(($G12-BC12)/$G12,0) -> 0 | BJ12: =IFERROR(BI12*$D12,0) -> 0 | BK12: =IFERROR(($G12-BI12)/$G12,0) -> 0 | BP12: =IFERROR(BO12*$D12,0) -> 0 | BQ12: =IFERROR(($G12-BO12)/$G12,0) -> 0 | BV12: =IFERROR(BU12*$D12,0) -> 0 | BW12: =IFERROR(($G12-BU12)/$G12,0) -> 0 | CB12: =IFERROR(CA12*$D12,0) -> 0 | CC12: =IFERROR(($G12-CA12)/$G12,0) -> 0 | CH12: =IFERROR(CG12*$D12,0) -> 0 | CI12: =IFERROR(($G12-CG12)/$G12,0) -> 0 | CN12: =IFERROR(CM12*$D12,0) -> 0 | CO12: =IFERROR(($G12-CM12)/$G12,0) -> 0
A13: 3 | I13: =G13*D13 -> 0 | L13: =IFERROR((J13-N13)/J13,0) -> 0 | M13: =IF(N13>0,IF(N13=AK13,$AJ$9,IF(N13=AQ13,$AP$9,IF(N13=AW13,$AV$9,IF(N13=BC13,$BB$9,IF(N13=BI13,$BH$9,IF(N13=BO13,$BN$9,IF(N13=BU13,$BT$9,IF(N13=CA13,$BZ$9,IF(N13=CG13,$CF$9,IF(N13=CM13,$CL$9,"")))))))))),"") | N13: =IF(X13>0,X13,Z13) -> 0 | O13: =IFERROR(N13*D13,"") -> 0 | P13: =MIN(IF($AO13=Reference!$A$10,100000000,AJ13),IF($AU13=Reference!$A$10,100000000,AP13),IF($BA13=Reference!$A$10,100000000,AV13),IF($BG13=Reference!$A$10,100000000,BB13),IF($BM13=Reference!$A$10,100000000,BH13),IF($BS13=Reference!$A$10,100000000,BN13),IF($BY13=Reference!$A$10,100000000,BT13),IF($CE13=Reference!$A$10,100000000,BZ13),IF($CK13=Reference!$A$10,100000000,CF13),IF($CQ13=Reference!$A$10,100000000,CL13)) -> 0 | Q13: =W13=F13 -> FALSE | R13: =COUNT(BC13,AK13,AQ13,AW13,BI13,BO13,BU13,CA13,CG13,CM13) -> 0 | S13: =MIN(AK13,AQ13,AW13,BC13,BI13,BO13,BU13,CA13,CG13,CM13)=N13 -> TRUE | T13: =IFERROR(AVERAGE(AK13,AQ13,AW13,BC13,BI13,BO13,BU13,CA13,CG13,CM13),"") | U13: =IFERROR(((G13-T13)/G13),"") | V13: =$Z13=$N13 -> TRUE | W13: =IF(Z13=AK13,$AJ$9,IF(Z13=AQ13,$AP$9,IF(Z13=AW13,$AV$9,IF(Z13=BC13,$BB$9,IF(Z13=BI13,$BH$9,IF(Z13=BO13,$BN$9,IF(Z13=BU13,$BT$9,IF(Z13=CA13,$BZ$9,IF(Z13=CG13,$CF$9,IF(Z13=CM13,$CL$9,"")))))))))) -> VENDOR 1 | X13: =IF(AO13=Reference!$A$8,'Bid Tab (F&B Ops and CatMan) 10'!AK13,IF('Bid Tab (F&B Ops and CatMan) 10'!AU13=Reference!$A$8,'Bid Tab (F&B Ops and CatMan) 10'!AQ13,IF('Bid Tab (F&B Ops and CatMan) 10'!BA13=Reference!$A$8,'Bid Tab (F&B Ops and CatMan) 10'!AW13,IF('Bid Tab (F&B Ops and CatMan) 10'!BG13=Reference!$A$8,'Bid Tab (F&B Ops and CatMan) 10'!BC13,IF('Bid Tab (F&B Ops and CatMan) 10'!BM13=Reference!$A$8,'Bid Tab (F&B Ops and CatMan) 10'!BI13,IF('Bid Tab (F&B Ops and CatMan) 10'!BS13=Reference!$A$8,'Bid Tab (F&B Ops and CatMan) 10'!BO13,IF('Bid Tab (F&B Ops and CatMan) 10'!BY13=Reference!$A$8,'Bid Tab (F&B Ops and CatMan) 10'!BU13,IF('Bid Tab (F&B Ops and CatMan) 10'!CE13=Reference!$A$8,'Bid Tab (F&B Ops and CatMan) 10'!CA13,IF('Bid Tab (F&B Ops and CatMan) 10'!CK13=Reference!$A$8,'Bid Tab (F&B Ops and CatMan) 10'!CG13,IF('Bid Tab (F&B Ops and CatMan) 10'!CQ13=Reference!$A$8,'Bid Tab (F&B Ops and CatMan) 10'!CM13,0)))))))))) -> 0 | Y13: =IFERROR(IF(Reference!$A$8=HLOOKUP(Reference!$A$8,'Bid Tab (F&B Ops and CatMan) 10'!AJ13:CQ13,1,0),TRUE,FALSE),FALSE) -> FALSE | Z13: =MIN(IF(AO13=Reference!$A$10,100000000,AK13),IF(AU13=Reference!$A$10,100000000,AQ13),IF(BA13=Reference!$A$10,100000000,AW13),IF(BG13=Reference!$A$10,100000000,BC13),IF(BM13=Reference!$A$10,100000000,BI13),IF(BS13=Reference!$A$10,100000000,BO13),IF(BY13=Reference!$A$10,100000000,BU13),IF(CE13=Reference!$A$10,100000000,CA13),IF(CK13=Reference!$A$10,100000000,CG13),IF(CQ13=Reference!$A$10,100000000,CM13)) -> 0 | AA13: =IF(X13>0,X13*D13,Z13*D13) -> 0 | AB13: =IF(Reference!A20>0,Reference!A20,MAX(IF(TODAY()-H13<365,IF(G13>=N13,G13,P13),P13),G13)) -> 0 | AC13: =IF(AE13>0,AB13*$D13,O13) -> 0 | AD13: =IF(N13>$AB13,0,(($AB13-N13))) -> 0 | AE13: =IF(N13>$AB13,0,(($AB13-N13)*$D13)) -> 0 | AF13: =IF(AND((AD13=0),(F13=M13),(G13=N13),(TODAY()-H13<365)),"PRICE EXTENSION",IF(AND(G13=AB13,G13>0),"LAST SYSTEM PRICE",IF(AB13>0,"INITIAL LOWEST BID"," "))) | AG13: =IF(G13>0,G13-Z13,0) -> 0 | AH13: =AG13*D13 -> 0 | AI13: =IFERROR((G13-Z13)/G13,0) -> 0 | AL13: =IFERROR(AK13*$D13,0) -> 0 | AM13: =IFERROR(($G13-AK13)/$G13,0) -> 0 | AR13: =IFERROR(AQ13*$D13,0) -> 0 | AS13: =IFERROR(($G13-AQ13)/$G13,0) -> 0 | AX13: =IFERROR(AW13*$D13,0) -> 0 | AY13: =IFERROR(($G13-AW13)/$G13,0) -> 0 | BD13: =IFERROR(BC13*$D13,0) -> 0 | BE13: =IFERROR(($G13-BC13)/$G13,0) -> 0 | BJ13: =IFERROR(BI13*$D13,0) -> 0 | BK13: =IFERROR(($G13-BI13)/$G13,0) -> 0 | BP13: =IFERROR(BO13*$D13,0) -> 0 | BQ13: =IFERROR(($G13-BO13)/$G13,0) -> 0 | BV13: =IFERROR(BU13*$D13,0) -> 0 | BW13: =IFERROR(($G13-BU13)/$G13,0) -> 0 | CB13: =IFERROR(CA13*$D13,0) -> 0 | CC13: =IFERROR(($G13-CA13)/$G13,0) -> 0 | CH13: =IFERROR(CG13*$D13,0) -> 0 | CI13: =IFERROR(($G13-CG13)/$G13,0) -> 0 | CN13: =IFERROR(CM13*$D13,0) -> 0 | CO13: =IFERROR(($G13-CM13)/$G13,0) -> 0
A14: 4 | I14: =G14*D14 -> 0 | L14: =IFERROR((J14-N14)/J14,0) -> 0 | M14: =IF(N14>0,IF(N14=AK14,$AJ$9,IF(N14=AQ14,$AP$9,IF(N14=AW14,$AV$9,IF(N14=BC14,$BB$9,IF(N14=BI14,$BH$9,IF(N14=BO14,$BN$9,IF(N14=BU14,$BT$9,IF(N14=CA14,$BZ$9,IF(N14=CG14,$CF$9,IF(N14=CM14,$CL$9,"")))))))))),"") | N14: =IF(X14>0,X14,Z14) -> 0 | O14: =IFERROR(N14*D14,"") -> 0 | P14: =MIN(IF($AO14=Reference!$A$10,100000000,AJ14),IF($AU14=Reference!$A$10,100000000,AP14),IF($BA14=Reference!$A$10,100000000,AV14),IF($BG14=Reference!$A$10,100000000,BB14),IF($BM14=Reference!$A$10,100000000,BH14),IF($BS14=Reference!$A$10,100000000,BN14),IF($BY14=Reference!$A$10,100000000,BT14),IF($CE14=Reference!$A$10,100000000,BZ14),IF($CK14=Reference!$A$10,100000000,CF14),IF($CQ14=Reference!$A$10,100000000,CL14)) -> 0 | Q14: =W14=F14 -> FALSE | R14: =COUNT(BC14,AK14,AQ14,AW14,BI14,BO14,BU14,CA14,CG14,CM14) -> 0 | S14: =MIN(AK14,AQ14,AW14,BC14,BI14,BO14,BU14,CA14,CG14,CM14)=N14 -> TRUE | T14: =IFERROR(AVERAGE(AK14,AQ14,AW14,BC14,BI14,BO14,BU14,CA14,CG14,CM14),"") | U14: =IFERROR(((G14-T14)/G14),"") | V14: =$Z14=$N14 -> TRUE | W14: =IF(Z14=AK14,$AJ$9,IF(Z14=AQ14,$AP$9,IF(Z14=AW14,$AV$9,IF(Z14=BC14,$BB$9,IF(Z14=BI14,$BH$9,IF(Z14=BO14,$BN$9,IF(Z14=BU14,$BT$9,IF(Z14=CA14,$BZ$9,IF(Z14=CG14,$CF$9,IF(Z14=CM14,$CL$9,"")))))))))) -> VENDOR 1 | X14: =IF(AO14=Reference!$A$8,'Bid Tab (F&B Ops and CatMan) 10'!AK14,IF('Bid Tab (F&B Ops and CatMan) 10'!AU14=Reference!$A$8,'Bid Tab (F&B Ops and CatMan) 10'!AQ14,IF('Bid Tab (F&B Ops and CatMan) 10'!BA14=Reference!$A$8,'Bid Tab (F&B Ops and CatMan) 10'!AW14,IF('Bid Tab (F&B Ops and CatMan) 10'!BG14=Reference!$A$8,'Bid Tab (F&B Ops and CatMan) 10'!BC14,IF('Bid Tab (F&B Ops and CatMan) 10'!BM14=Reference!$A$8,'Bid Tab (F&B Ops and CatMan) 10'!BI14,IF('Bid Tab (F&B Ops and CatMan) 10'!BS14=Reference!$A$8,'Bid Tab (F&B Ops and CatMan) 10'!BO14,IF('Bid Tab (F&B Ops and CatMan) 10'!BY14=Reference!$A$8,'Bid Tab (F&B Ops and CatMan) 10'!BU14,IF('Bid Tab (F&B Ops and CatMan) 10'!CE14=Reference!$A$8,'Bid Tab (F&B Ops and CatMan) 10'!CA14,IF('Bid Tab (F&B Ops and CatMan) 10'!CK14=Reference!$A$8,'Bid Tab (F&B Ops and CatMan) 10'!CG14,IF('Bid Tab (F&B Ops and CatMan) 10'!CQ14=Reference!$A$8,'Bid Tab (F&B Ops and CatMan) 10'!CM14,0)))))))))) -> 0 | Y14: =IFERROR(IF(Reference!$A$8=HLOOKUP(Reference!$A$8,'Bid Tab (F&B Ops and CatMan) 10'!AJ14:CQ14,1,0),TRUE,FALSE),FALSE) -> FALSE | Z14: =MIN(IF(AO14=Reference!$A$10,100000000,AK14),IF(AU14=Reference!$A$10,100000000,AQ14),IF(BA14=Reference!$A$10,100000000,AW14),IF(BG14=Reference!$A$10,100000000,BC14),IF(BM14=Reference!$A$10,100000000,BI14),IF(BS14=Reference!$A$10,100000000,BO14),IF(BY14=Reference!$A$10,100000000,BU14),IF(CE14=Reference!$A$10,100000000,CA14),IF(CK14=Reference!$A$10,100000000,CG14),IF(CQ14=Reference!$A$10,100000000,CM14)) -> 0 | AA14: =IF(X14>0,X14*D14,Z14*D14) -> 0 | AB14: =IF(Reference!A21>0,Reference!A21,MAX(IF(TODAY()-H14<365,IF(G14>=N14,G14,P14),P14),G14)) -> 0 | AC14: =IF(AE14>0,AB14*$D14,O14) -> 0 | AD14: =IF(N14>$AB14,0,(($AB14-N14))) -> 0 | AE14: =IF(N14>$AB14,0,(($AB14-N14)*$D14)) -> 0 | AF14: =IF(AND((AD14=0),(F14=M14),(G14=N14),(TODAY()-H14<365)),"PRICE EXTENSION",IF(AND(G14=AB14,G14>0),"LAST SYSTEM PRICE",IF(AB14>0,"INITIAL LOWEST BID"," "))) | AG14: =IF(G14>0,G14-Z14,0) -> 0 | AH14: =AG14*D14 -> 0 | AI14: =IFERROR((G14-Z14)/G14,0) -> 0 | AL14: =IFERROR(AK14*$D14,0) -> 0 | AM14: =IFERROR(($G14-AK14)/$G14,0) -> 0 | AR14: =IFERROR(AQ14*$D14,0) -> 0 | AS14: =IFERROR(($G14-AQ14)/$G14,0) -> 0 | AX14: =IFERROR(AW14*$D14,0) -> 0 | AY14: =IFERROR(($G14-AW14)/$G14,0) -> 0 | BD14: =IFERROR(BC14*$D14,0) -> 0 | BE14: =IFERROR(($G14-BC14)/$G14,0) -> 0 | BJ14: =IFERROR(BI14*$D14,0) -> 0 | BK14: =IFERROR(($G14-BI14)/$G14,0) -> 0 | BP14: =IFERROR(BO14*$D14,0) -> 0 | BQ14: =IFERROR(($G14-BO14)/$G14,0) -> 0 | BV14: =IFERROR(BU14*$D14,0) -> 0 | BW14: =IFERROR(($G14-BU14)/$G14,0) -> 0 | CB14: =IFERROR(CA14*$D14,0) -> 0 | CC14: =IFERROR(($G14-CA14)/$G14,0) -> 0 | CH14: =IFERROR(CG14*$D14,0) -> 0 | CI14: =IFERROR(($G14-CG14)/$G14,0) -> 0 | CN14: =IFERROR(CM14*$D14,0) -> 0 | CO14: =IFERROR(($G14-CM14)/$G14,0) -> 0
A15: 5 | I15: =G15*D15 -> 0 | L15: =IFERROR((J15-N15)/J15,0) -> 0 | M15: =IF(N15>0,IF(N15=AK15,$AJ$9,IF(N15=AQ15,$AP$9,IF(N15=AW15,$AV$9,IF(N15=BC15,$BB$9,IF(N15=BI15,$BH$9,IF(N15=BO15,$BN$9,IF(N15=BU15,$BT$9,IF(N15=CA15,$BZ$9,IF(N15=CG15,$CF$9,IF(N15=CM15,$CL$9,"")))))))))),"") | N15: =IF(X15>0,X15,Z15) -> 0 | O15: =IFERROR(N15*D15,"") -> 0 | P15: =MIN(IF($AO15=Reference!$A$10,100000000,AJ15),IF($AU15=Reference!$A$10,100000000,AP15),IF($BA15=Reference!$A$10,100000000,AV15),IF($BG15=Reference!$A$10,100000000,BB15),IF($BM15=Reference!$A$10,100000000,BH15),IF($BS15=Reference!$A$10,100000000,BN15),IF($BY15=Reference!$A$10,100000000,BT15),IF($CE15=Reference!$A$10,100000000,BZ15),IF($CK15=Reference!$A$10,100000000,CF15),IF($CQ15=Reference!$A$10,100000000,CL15)) -> 0 | Q15: =W15=F15 -> FALSE | R15: =COUNT(BC15,AK15,AQ15,AW15,BI15,BO15,BU15,CA15,CG15,CM15) -> 0 | S15: =MIN(AK15,AQ15,AW15,BC15,BI15,BO15,BU15,CA15,CG15,CM15)=N15 -> TRUE | T15: =IFERROR(AVERAGE(AK15,AQ15,AW15,BC15,BI15,BO15,BU15,CA15,CG15,CM15),"") | U15: =IFERROR(((G15-T15)/G15),"") | V15: =$Z15=$N15 -> TRUE | W15: =IF(Z15=AK15,$AJ$9,IF(Z15=AQ15,$AP$9,IF(Z15=AW15,$AV$9,IF(Z15=BC15,$BB$9,IF(Z15=BI15,$BH$9,IF(Z15=BO15,$BN$9,IF(Z15=BU15,$BT$9,IF(Z15=CA15,$BZ$9,IF(Z15=CG15,$CF$9,IF(Z15=CM15,$CL$9,"")))))))))) -> VENDOR 1 | X15: =IF(AO15=Reference!$A$8,'Bid Tab (F&B Ops and CatMan) 10'!AK15,IF('Bid Tab (F&B Ops and CatMan) 10'!AU15=Reference!$A$8,'Bid Tab (F&B Ops and CatMan) 10'!AQ15,IF('Bid Tab (F&B Ops and CatMan) 10'!BA15=Reference!$A$8,'Bid Tab (F&B Ops and CatMan) 10'!AW15,IF('Bid Tab (F&B Ops and CatMan) 10'!BG15=Reference!$A$8,'Bid Tab (F&B Ops and CatMan) 10'!BC15,IF('Bid Tab (F&B Ops and CatMan) 10'!BM15=Reference!$A$8,'Bid Tab (F&B Ops and CatMan) 10'!BI15,IF('Bid Tab (F&B Ops and CatMan) 10'!BS15=Reference!$A$8,'Bid Tab (F&B Ops and CatMan) 10'!BO15,IF('Bid Tab (F&B Ops and CatMan) 10'!BY15=Reference!$A$8,'Bid Tab (F&B Ops and CatMan) 10'!BU15,IF('Bid Tab (F&B Ops and CatMan) 10'!CE15=Reference!$A$8,'Bid Tab (F&B Ops and CatMan) 10'!CA15,IF('Bid Tab (F&B Ops and CatMan) 10'!CK15=Reference!$A$8,'Bid Tab (F&B Ops and CatMan) 10'!CG15,IF('Bid Tab (F&B Ops and CatMan) 10'!CQ15=Reference!$A$8,'Bid Tab (F&B Ops and CatMan) 10'!CM15,0)))))))))) -> 0 | Y15: =IFERROR(IF(Reference!$A$8=HLOOKUP(Reference!$A$8,'Bid Tab (F&B Ops and CatMan) 10'!AJ15:CQ15,1,0),TRUE,FALSE),FALSE) -> FALSE | Z15: =MIN(IF(AO15=Reference!$A$10,100000000,AK15),IF(AU15=Reference!$A$10,100000000,AQ15),IF(BA15=Reference!$A$10,100000000,AW15),IF(BG15=Reference!$A$10,100000000,BC15),IF(BM15=Reference!$A$10,100000000,BI15),IF(BS15=Reference!$A$10,100000000,BO15),IF(BY15=Reference!$A$10,100000000,BU15),IF(CE15=Reference!$A$10,100000000,CA15),IF(CK15=Reference!$A$10,100000000,CG15),IF(CQ15=Reference!$A$10,100000000,CM15)) -> 0 | AA15: =IF(X15>0,X15*D15,Z15*D15) -> 0 | AB15: =IF(Reference!A22>0,Reference!A22,MAX(IF(TODAY()-H15<365,IF(G15>=N15,G15,P15),P15),G15)) -> 0 | AC15: =IF(AE15>0,AB15*$D15,O15) -> 0 | AD15: =IF(N15>$AB15,0,(($AB15-N15))) -> 0 | AE15: =IF(N15>$AB15,0,(($AB15-N15)*$D15)) -> 0 | AF15: =IF(AND((AD15=0),(F15=M15),(G15=N15),(TODAY()-H15<365)),"PRICE EXTENSION",IF(AND(G15=AB15,G15>0),"LAST SYSTEM PRICE",IF(AB15>0,"INITIAL LOWEST BID"," "))) | AG15: =IF(G15>0,G15-Z15,0) -> 0 | AH15: =AG15*D15 -> 0 | AI15: =IFERROR((G15-Z15)/G15,0) -> 0 | AL15: =IFERROR(AK15*$D15,0) -> 0 | AM15: =IFERROR(($G15-AK15)/$G15,0) -> 0 | AR15: =IFERROR(AQ15*$D15,0) -> 0 | AS15: =IFERROR(($G15-AQ15)/$G15,0) -> 0 | AX15: =IFERROR(AW15*$D15,0) -> 0 | AY15: =IFERROR(($G15-AW15)/$G15,0) -> 0 | BD15: =IFERROR(BC15*$D15,0) -> 0 | BE15: =IFERROR(($G15-BC15)/$G15,0) -> 0 | BJ15: =IFERROR(BI15*$D15,0) -> 0 | BK15: =IFERROR(($G15-BI15)/$G15,0) -> 0 | BP15: =IFERROR(BO15*$D15,0) -> 0 | BQ15: =IFERROR(($G15-BO15)/$G15,0) -> 0 | BV15: =IFERROR(BU15*$D15,0) -> 0 | BW15: =IFERROR(($G15-BU15)/$G15,0) -> 0 | CB15: =IFERROR(CA15*$D15,0) -> 0 | CC15: =IFERROR(($G15-CA15)/$G15,0) -> 0 | CH15: =IFERROR(CG15*$D15,0) -> 0 | CI15: =IFERROR(($G15-CG15)/$G15,0) -> 0 | CN15: =IFERROR(CM15*$D15,0) -> 0 | CO15: =IFERROR(($G15-CM15)/$G15,0) -> 0
A16: 6 | I16: =G16*D16 -> 0 | L16: =IFERROR((J16-N16)/J16,0) -> 0 | M16: =IF(N16>0,IF(N16=AK16,$AJ$9,IF(N16=AQ16,$AP$9,IF(N16=AW16,$AV$9,IF(N16=BC16,$BB$9,IF(N16=BI16,$BH$9,IF(N16=BO16,$BN$9,IF(N16=BU16,$BT$9,IF(N16=CA16,$BZ$9,IF(N16=CG16,$CF$9,IF(N16=CM16,$CL$9,"")))))))))),"") | N16: =IF(X16>0,X16,Z16) -> 0 | O16: =IFERROR(N16*D16,"") -> 0 | P16: =MIN(IF($AO16=Reference!$A$10,100000000,AJ16),IF($AU16=Reference!$A$10,100000000,AP16),IF($BA16=Reference!$A$10,100000000,AV16),IF($BG16=Reference!$A$10,100000000,BB16),IF($BM16=Reference!$A$10,100000000,BH16),IF($BS16=Reference!$A$10,100000000,BN16),IF($BY16=Reference!$A$10,100000000,BT16),IF($CE16=Reference!$A$10,100000000,BZ16),IF($CK16=Reference!$A$10,100000000,CF16),IF($CQ16=Reference!$A$10,100000000,CL16)) -> 0 | Q16: =W16=F16 -> FALSE | R16: =COUNT(BC16,AK16,AQ16,AW16,BI16,BO16,BU16,CA16,CG16,CM16) -> 0 | S16: =MIN(AK16,AQ16,AW16,BC16,BI16,BO16,BU16,CA16,CG16,CM16)=N16 -> TRUE | T16: =IFERROR(AVERAGE(AK16,AQ16,AW16,BC16,BI16,BO16,BU16,CA16,CG16,CM16),"") | U16: =IFERROR(((G16-T16)/G16),"") | V16: =$Z16=$N16 -> TRUE | W16: =IF(Z16=AK16,$AJ$9,IF(Z16=AQ16,$AP$9,IF(Z16=AW16,$AV$9,IF(Z16=BC16,$BB$9,IF(Z16=BI16,$BH$9,IF(Z16=BO16,$BN$9,IF(Z16=BU16,$BT$9,IF(Z16=CA16,$BZ$9,IF(Z16=CG16,$CF$9,IF(Z16=CM16,$CL$9,"")))))))))) -> VENDOR 1 | X16: =IF(AO16=Reference!$A$8,'Bid Tab (F&B Ops and CatMan) 10'!AK16,IF('Bid Tab (F&B Ops and CatMan) 10'!AU16=Reference!$A$8,'Bid Tab (F&B Ops and CatMan) 10'!AQ16,IF('Bid Tab (F&B Ops and CatMan) 10'!BA16=Reference!$A$8,'Bid Tab (F&B Ops and CatMan) 10'!AW16,IF('Bid Tab (F&B Ops and CatMan) 10'!BG16=Reference!$A$8,'Bid Tab (F&B Ops and CatMan) 10'!BC16,IF('Bid Tab (F&B Ops and CatMan) 10'!BM16=Reference!$A$8,'Bid Tab (F&B Ops and CatMan) 10'!BI16,IF('Bid Tab (F&B Ops and CatMan) 10'!BS16=Reference!$A$8,'Bid Tab (F&B Ops and CatMan) 10'!BO16,IF('Bid Tab (F&B Ops and CatMan) 10'!BY16=Reference!$A$8,'Bid Tab (F&B Ops and CatMan) 10'!BU16,IF('Bid Tab (F&B Ops and CatMan) 10'!CE16=Reference!$A$8,'Bid Tab (F&B Ops and CatMan) 10'!CA16,IF('Bid Tab (F&B Ops and CatMan) 10'!CK16=Reference!$A$8,'Bid Tab (F&B Ops and CatMan) 10'!CG16,IF('Bid Tab (F&B Ops and CatMan) 10'!CQ16=Reference!$A$8,'Bid Tab (F&B Ops and CatMan) 10'!CM16,0)))))))))) -> 0 | Y16: =IFERROR(IF(Reference!$A$8=HLOOKUP(Reference!$A$8,'Bid Tab (F&B Ops and CatMan) 10'!AJ16:CQ16,1,0),TRUE,FALSE),FALSE) -> FALSE | Z16: =MIN(IF(AO16=Reference!$A$10,100000000,AK16),IF(AU16=Reference!$A$10,100000000,AQ16),IF(BA16=Reference!$A$10,100000000,AW16),IF(BG16=Reference!$A$10,100000000,BC16),IF(BM16=Reference!$A$10,100000000,BI16),IF(BS16=Reference!$A$10,100000000,BO16),IF(BY16=Reference!$A$10,100000000,BU16),IF(CE16=Reference!$A$10,100000000,CA16),IF(CK16=Reference!$A$10,100000000,CG16),IF(CQ16=Reference!$A$10,100000000,CM16)) -> 0 | AA16: =IF(X16>0,X16*D16,Z16*D16) -> 0 | AB16: =IF(Reference!A23>0,Reference!A23,MAX(IF(TODAY()-H16<365,IF(G16>=N16,G16,P16),P16),G16)) -> 0 | AC16: =IF(AE16>0,AB16*$D16,O16) -> 0 | AD16: =IF(N16>$AB16,0,(($AB16-N16))) -> 0 | AE16: =IF(N16>$AB16,0,(($AB16-N16)*$D16)) -> 0 | AF16: =IF(AND((AD16=0),(F16=M16),(G16=N16),(TODAY()-H16<365)),"PRICE EXTENSION",IF(AND(G16=AB16,G16>0),"LAST SYSTEM PRICE",IF(AB16>0,"INITIAL LOWEST BID"," "))) | AG16: =IF(G16>0,G16-Z16,0) -> 0 | AH16: =AG16*D16 -> 0 | AI16: =IFERROR((G16-Z16)/G16,0) -> 0 | AL16: =IFERROR(AK16*$D16,0) -> 0 | AM16: =IFERROR(($G16-AK16)/$G16,0) -> 0 | AR16: =IFERROR(AQ16*$D16,0) -> 0 | AS16: =IFERROR(($G16-AQ16)/$G16,0) -> 0 | AX16: =IFERROR(AW16*$D16,0) -> 0 | AY16: =IFERROR(($G16-AW16)/$G16,0) -> 0 | BD16: =IFERROR(BC16*$D16,0) -> 0 | BE16: =IFERROR(($G16-BC16)/$G16,0) -> 0 | BJ16: =IFERROR(BI16*$D16,0) -> 0 | BK16: =IFERROR(($G16-BI16)/$G16,0) -> 0 | BP16: =IFERROR(BO16*$D16,0) -> 0 | BQ16: =IFERROR(($G16-BO16)/$G16,0) -> 0 | BV16: =IFERROR(BU16*$D16,0) -> 0 | BW16: =IFERROR(($G16-BU16)/$G16,0) -> 0 | CB16: =IFERROR(CA16*$D16,0) -> 0 | CC16: =IFERROR(($G16-CA16)/$G16,0) -> 0 | CH16: =IFERROR(CG16*$D16,0) -> 0 | CI16: =IFERROR(($G16-CG16)/$G16,0) -> 0 | CN16: =IFERROR(CM16*$D16,0) -> 0 | CO16: =IFERROR(($G16-CM16)/$G16,0) -> 0
A17: 7 | I17: =G17*D17 -> 0 | L17: =IFERROR((J17-N17)/J17,0) -> 0 | M17: =IF(N17>0,IF(N17=AK17,$AJ$9,IF(N17=AQ17,$AP$9,IF(N17=AW17,$AV$9,IF(N17=BC17,$BB$9,IF(N17=BI17,$BH$9,IF(N17=BO17,$BN$9,IF(N17=BU17,$BT$9,IF(N17=CA17,$BZ$9,IF(N17=CG17,$CF$9,IF(N17=CM17,$CL$9,"")))))))))),"") | N17: =IF(X17>0,X17,Z17) -> 0 | O17: =IFERROR(N17*D17,"") -> 0 | P17: =MIN(IF($AO17=Reference!$A$10,100000000,AJ17),IF($AU17=Reference!$A$10,100000000,AP17),IF($BA17=Reference!$A$10,100000000,AV17),IF($BG17=Reference!$A$10,100000000,BB17),IF($BM17=Reference!$A$10,100000000,BH17),IF($BS17=Reference!$A$10,100000000,BN17),IF($BY17=Reference!$A$10,100000000,BT17),IF($CE17=Reference!$A$10,100000000,BZ17),IF($CK17=Reference!$A$10,100000000,CF17),IF($CQ17=Reference!$A$10,100000000,CL17)) -> 0 | Q17: =W17=F17 -> FALSE | R17: =COUNT(BC17,AK17,AQ17,AW17,BI17,BO17,BU17,CA17,CG17,CM17) -> 0 | S17: =MIN(AK17,AQ17,AW17,BC17,BI17,BO17,BU17,CA17,CG17,CM17)=N17 -> TRUE | T17: =IFERROR(AVERAGE(AK17,AQ17,AW17,BC17,BI17,BO17,BU17,CA17,CG17,CM17),"") | U17: =IFERROR(((G17-T17)/G17),"") | V17: =$Z17=$N17 -> TRUE | W17: =IF(Z17=AK17,$AJ$9,IF(Z17=AQ17,$AP$9,IF(Z17=AW17,$AV$9,IF(Z17=BC17,$BB$9,IF(Z17=BI17,$BH$9,IF(Z17=BO17,$BN$9,IF(Z17=BU17,$BT$9,IF(Z17=CA17,$BZ$9,IF(Z17=CG17,$CF$9,IF(Z17=CM17,$CL$9,"")))))))))) -> VENDOR 1 | X17: =IF(AO17=Reference!$A$8,'Bid Tab (F&B Ops and CatMan) 10'!AK17,IF('Bid Tab (F&B Ops and CatMan) 10'!AU17=Reference!$A$8,'Bid Tab (F&B Ops and CatMan) 10'!AQ17,IF('Bid Tab (F&B Ops and CatMan) 10'!BA17=Reference!$A$8,'Bid Tab (F&B Ops and CatMan) 10'!AW17,IF('Bid Tab (F&B Ops and CatMan) 10'!BG17=Reference!$A$8,'Bid Tab (F&B Ops and CatMan) 10'!BC17,IF('Bid Tab (F&B Ops and CatMan) 10'!BM17=Reference!$A$8,'Bid Tab (F&B Ops and CatMan) 10'!BI17,IF('Bid Tab (F&B Ops and CatMan) 10'!BS17=Reference!$A$8,'Bid Tab (F&B Ops and CatMan) 10'!BO17,IF('Bid Tab (F&B Ops and CatMan) 10'!BY17=Reference!$A$8,'Bid Tab (F&B Ops and CatMan) 10'!BU17,IF('Bid Tab (F&B Ops and CatMan) 10'!CE17=Reference!$A$8,'Bid Tab (F&B Ops and CatMan) 10'!CA17,IF('Bid Tab (F&B Ops and CatMan) 10'!CK17=Reference!$A$8,'Bid Tab (F&B Ops and CatMan) 10'!CG17,IF('Bid Tab (F&B Ops and CatMan) 10'!CQ17=Reference!$A$8,'Bid Tab (F&B Ops and CatMan) 10'!CM17,0)))))))))) -> 0 | Y17: =IFERROR(IF(Reference!$A$8=HLOOKUP(Reference!$A$8,'Bid Tab (F&B Ops and CatMan) 10'!AJ17:CQ17,1,0),TRUE,FALSE),FALSE) -> FALSE | Z17: =MIN(IF(AO17=Reference!$A$10,100000000,AK17),IF(AU17=Reference!$A$10,100000000,AQ17),IF(BA17=Reference!$A$10,100000000,AW17),IF(BG17=Reference!$A$10,100000000,BC17),IF(BM17=Reference!$A$10,100000000,BI17),IF(BS17=Reference!$A$10,100000000,BO17),IF(BY17=Reference!$A$10,100000000,BU17),IF(CE17=Reference!$A$10,100000000,CA17),IF(CK17=Reference!$A$10,100000000,CG17),IF(CQ17=Reference!$A$10,100000000,CM17)) -> 0 | AA17: =IF(X17>0,X17*D17,Z17*D17) -> 0 | AB17: =IF(Reference!A24>0,Reference!A24,MAX(IF(TODAY()-H17<365,IF(G17>=N17,G17,P17),P17),G17)) -> 0 | AC17: =IF(AE17>0,AB17*$D17,O17) -> 0 | AD17: =IF(N17>$AB17,0,(($AB17-N17))) -> 0 | AE17: =IF(N17>$AB17,0,(($AB17-N17)*$D17)) -> 0 | AF17: =IF(AND((AD17=0),(F17=M17),(G17=N17),(TODAY()-H17<365)),"PRICE EXTENSION",IF(AND(G17=AB17,G17>0),"LAST SYSTEM PRICE",IF(AB17>0,"INITIAL LOWEST BID"," "))) | AG17: =IF(G17>0,G17-Z17,0) -> 0 | AH17: =AG17*D17 -> 0 | AI17: =IFERROR((G17-Z17)/G17,0) -> 0 | AL17: =IFERROR(AK17*$D17,0) -> 0 | AM17: =IFERROR(($G17-AK17)/$G17,0) -> 0 | AR17: =IFERROR(AQ17*$D17,0) -> 0 | AS17: =IFERROR(($G17-AQ17)/$G17,0) -> 0 | AX17: =IFERROR(AW17*$D17,0) -> 0 | AY17: =IFERROR(($G17-AW17)/$G17,0) -> 0 | BD17: =IFERROR(BC17*$D17,0) -> 0 | BE17: =IFERROR(($G17-BC17)/$G17,0) -> 0 | BJ17: =IFERROR(BI17*$D17,0) -> 0 | BK17: =IFERROR(($G17-BI17)/$G17,0) -> 0 | BP17: =IFERROR(BO17*$D17,0) -> 0 | BQ17: =IFERROR(($G17-BO17)/$G17,0) -> 0 | BV17: =IFERROR(BU17*$D17,0) -> 0 | BW17: =IFERROR(($G17-BU17)/$G17,0) -> 0 | CB17: =IFERROR(CA17*$D17,0) -> 0 | CC17: =IFERROR(($G17-CA17)/$G17,0) -> 0 | CH17: =IFERROR(CG17*$D17,0) -> 0 | CI17: =IFERROR(($G17-CG17)/$G17,0) -> 0 | CN17: =IFERROR(CM17*$D17,0) -> 0 | CO17: =IFERROR(($G17-CM17)/$G17,0) -> 0
A18: 8 | I18: =G18*D18 -> 0 | L18: =IFERROR((J18-N18)/J18,0) -> 0 | M18: =IF(N18>0,IF(N18=AK18,$AJ$9,IF(N18=AQ18,$AP$9,IF(N18=AW18,$AV$9,IF(N18=BC18,$BB$9,IF(N18=BI18,$BH$9,IF(N18=BO18,$BN$9,IF(N18=BU18,$BT$9,IF(N18=CA18,$BZ$9,IF(N18=CG18,$CF$9,IF(N18=CM18,$CL$9,"")))))))))),"") | N18: =IF(X18>0,X18,Z18) -> 0 | O18: =IFERROR(N18*D18,"") -> 0 | P18: =MIN(IF($AO18=Reference!$A$10,100000000,AJ18),IF($AU18=Reference!$A$10,100000000,AP18),IF($BA18=Reference!$A$10,100000000,AV18),IF($BG18=Reference!$A$10,100000000,BB18),IF($BM18=Reference!$A$10,100000000,BH18),IF($BS18=Reference!$A$10,100000000,BN18),IF($BY18=Reference!$A$10,100000000,BT18),IF($CE18=Reference!$A$10,100000000,BZ18),IF($CK18=Reference!$A$10,100000000,CF18),IF($CQ18=Reference!$A$10,100000000,CL18)) -> 0 | Q18: =W18=F18 -> FALSE | R18: =COUNT(BC18,AK18,AQ18,AW18,BI18,BO18,BU18,CA18,CG18,CM18) -> 0 | S18: =MIN(AK18,AQ18,AW18,BC18,BI18,BO18,BU18,CA18,CG18,CM18)=N18 -> TRUE | T18: =IFERROR(AVERAGE(AK18,AQ18,AW18,BC18,BI18,BO18,BU18,CA18,CG18,CM18),"") | U18: =IFERROR(((G18-T18)/G18),"") | V18: =$Z18=$N18 -> TRUE | W18: =IF(Z18=AK18,$AJ$9,IF(Z18=AQ18,$AP$9,IF(Z18=AW18,$AV$9,IF(Z18=BC18,$BB$9,IF(Z18=BI18,$BH$9,IF(Z18=BO18,$BN$9,IF(Z18=BU18,$BT$9,IF(Z18=CA18,$BZ$9,IF(Z18=CG18,$CF$9,IF(Z18=CM18,$CL$9,"")))))))))) -> VENDOR 1 | X18: =IF(AO18=Reference!$A$8,'Bid Tab (F&B Ops and CatMan) 10'!AK18,IF('Bid Tab (F&B Ops and CatMan) 10'!AU18=Reference!$A$8,'Bid Tab (F&B Ops and CatMan) 10'!AQ18,IF('Bid Tab (F&B Ops and CatMan) 10'!BA18=Reference!$A$8,'Bid Tab (F&B Ops and CatMan) 10'!AW18,IF('Bid Tab (F&B Ops and CatMan) 10'!BG18=Reference!$A$8,'Bid Tab (F&B Ops and CatMan) 10'!BC18,IF('Bid Tab (F&B Ops and CatMan) 10'!BM18=Reference!$A$8,'Bid Tab (F&B Ops and CatMan) 10'!BI18,IF('Bid Tab (F&B Ops and CatMan) 10'!BS18=Reference!$A$8,'Bid Tab (F&B Ops and CatMan) 10'!BO18,IF('Bid Tab (F&B Ops and CatMan) 10'!BY18=Reference!$A$8,'Bid Tab (F&B Ops and CatMan) 10'!BU18,IF('Bid Tab (F&B Ops and CatMan) 10'!CE18=Reference!$A$8,'Bid Tab (F&B Ops and CatMan) 10'!CA18,IF('Bid Tab (F&B Ops and CatMan) 10'!CK18=Reference!$A$8,'Bid Tab (F&B Ops and CatMan) 10'!CG18,IF('Bid Tab (F&B Ops and CatMan) 10'!CQ18=Reference!$A$8,'Bid Tab (F&B Ops and CatMan) 10'!CM18,0)))))))))) -> 0 | Y18: =IFERROR(IF(Reference!$A$8=HLOOKUP(Reference!$A$8,'Bid Tab (F&B Ops and CatMan) 10'!AJ18:CQ18,1,0),TRUE,FALSE),FALSE) -> FALSE | Z18: =MIN(IF(AO18=Reference!$A$10,100000000,AK18),IF(AU18=Reference!$A$10,100000000,AQ18),IF(BA18=Reference!$A$10,100000000,AW18),IF(BG18=Reference!$A$10,100000000,BC18),IF(BM18=Reference!$A$10,100000000,BI18),IF(BS18=Reference!$A$10,100000000,BO18),IF(BY18=Reference!$A$10,100000000,BU18),IF(CE18=Reference!$A$10,100000000,CA18),IF(CK18=Reference!$A$10,100000000,CG18),IF(CQ18=Reference!$A$10,100000000,CM18)) -> 0 | AA18: =IF(X18>0,X18*D18,Z18*D18) -> 0 | AB18: =IF(Reference!A25>0,Reference!A25,MAX(IF(TODAY()-H18<365,IF(G18>=N18,G18,P18),P18),G18)) -> 0 | AC18: =IF(AE18>0,AB18*$D18,O18) -> 0 | AD18: =IF(N18>$AB18,0,(($AB18-N18))) -> 0 | AE18: =IF(N18>$AB18,0,(($AB18-N18)*$D18)) -> 0 | AF18: =IF(AND((AD18=0),(F18=M18),(G18=N18),(TODAY()-H18<365)),"PRICE EXTENSION",IF(AND(G18=AB18,G18>0),"LAST SYSTEM PRICE",IF(AB18>0,"INITIAL LOWEST BID"," "))) | AG18: =IF(G18>0,G18-Z18,0) -> 0 | AH18: =AG18*D18 -> 0 | AI18: =IFERROR((G18-Z18)/G18,0) -> 0 | AL18: =IFERROR(AK18*$D18,0) -> 0 | AM18: =IFERROR(($G18-AK18)/$G18,0) -> 0 | AR18: =IFERROR(AQ18*$D18,0) -> 0 | AS18: =IFERROR(($G18-AQ18)/$G18,0) -> 0 | AX18: =IFERROR(AW18*$D18,0) -> 0 | AY18: =IFERROR(($G18-AW18)/$G18,0) -> 0 | BD18: =IFERROR(BC18*$D18,0) -> 0 | BE18: =IFERROR(($G18-BC18)/$G18,0) -> 0 | BJ18: =IFERROR(BI18*$D18,0) -> 0 | BK18: =IFERROR(($G18-BI18)/$G18,0) -> 0 | BP18: =IFERROR(BO18*$D18,0) -> 0 | BQ18: =IFERROR(($G18-BO18)/$G18,0) -> 0 | BV18: =IFERROR(BU18*$D18,0) -> 0 | BW18: =IFERROR(($G18-BU18)/$G18,0) -> 0 | CB18: =IFERROR(CA18*$D18,0) -> 0 | CC18: =IFERROR(($G18-CA18)/$G18,0) -> 0 | CH18: =IFERROR(CG18*$D18,0) -> 0 | CI18: =IFERROR(($G18-CG18)/$G18,0) -> 0 | CN18: =IFERROR(CM18*$D18,0) -> 0 | CO18: =IFERROR(($G18-CM18)/$G18,0) -> 0
A19: 9 | I19: =G19*D19 -> 0 | L19: =IFERROR((J19-N19)/J19,0) -> 0 | M19: =IF(N19>0,IF(N19=AK19,$AJ$9,IF(N19=AQ19,$AP$9,IF(N19=AW19,$AV$9,IF(N19=BC19,$BB$9,IF(N19=BI19,$BH$9,IF(N19=BO19,$BN$9,IF(N19=BU19,$BT$9,IF(N19=CA19,$BZ$9,IF(N19=CG19,$CF$9,IF(N19=CM19,$CL$9,"")))))))))),"") | N19: =IF(X19>0,X19,Z19) -> 0 | O19: =IFERROR(N19*D19,"") -> 0 | P19: =MIN(IF($AO19=Reference!$A$10,100000000,AJ19),IF($AU19=Reference!$A$10,100000000,AP19),IF($BA19=Reference!$A$10,100000000,AV19),IF($BG19=Reference!$A$10,100000000,BB19),IF($BM19=Reference!$A$10,100000000,BH19),IF($BS19=Reference!$A$10,100000000,BN19),IF($BY19=Reference!$A$10,100000000,BT19),IF($CE19=Reference!$A$10,100000000,BZ19),IF($CK19=Reference!$A$10,100000000,CF19),IF($CQ19=Reference!$A$10,100000000,CL19)) -> 0 | Q19: =W19=F19 -> FALSE | R19: =COUNT(BC19,AK19,AQ19,AW19,BI19,BO19,BU19,CA19,CG19,CM19) -> 0 | S19: =MIN(AK19,AQ19,AW19,BC19,BI19,BO19,BU19,CA19,CG19,CM19)=N19 -> TRUE | T19: =IFERROR(AVERAGE(AK19,AQ19,AW19,BC19,BI19,BO19,BU19,CA19,CG19,CM19),"") | U19: =IFERROR(((G19-T19)/G19),"") | V19: =$Z19=$N19 -> TRUE | W19: =IF(Z19=AK19,$AJ$9,IF(Z19=AQ19,$AP$9,IF(Z19=AW19,$AV$9,IF(Z19=BC19,$BB$9,IF(Z19=BI19,$BH$9,IF(Z19=BO19,$BN$9,IF(Z19=BU19,$BT$9,IF(Z19=CA19,$BZ$9,IF(Z19=CG19,$CF$9,IF(Z19=CM19,$CL$9,"")))))))))) -> VENDOR 1 | X19: =IF(AO19=Reference!$A$8,'Bid Tab (F&B Ops and CatMan) 10'!AK19,IF('Bid Tab (F&B Ops and CatMan) 10'!AU19=Reference!$A$8,'Bid Tab (F&B Ops and CatMan) 10'!AQ19,IF('Bid Tab (F&B Ops and CatMan) 10'!BA19=Reference!$A$8,'Bid Tab (F&B Ops and CatMan) 10'!AW19,IF('Bid Tab (F&B Ops and CatMan) 10'!BG19=Reference!$A$8,'Bid Tab (F&B Ops and CatMan) 10'!BC19,IF('Bid Tab (F&B Ops and CatMan) 10'!BM19=Reference!$A$8,'Bid Tab (F&B Ops and CatMan) 10'!BI19,IF('Bid Tab (F&B Ops and CatMan) 10'!BS19=Reference!$A$8,'Bid Tab (F&B Ops and CatMan) 10'!BO19,IF('Bid Tab (F&B Ops and CatMan) 10'!BY19=Reference!$A$8,'Bid Tab (F&B Ops and CatMan) 10'!BU19,IF('Bid Tab (F&B Ops and CatMan) 10'!CE19=Reference!$A$8,'Bid Tab (F&B Ops and CatMan) 10'!CA19,IF('Bid Tab (F&B Ops and CatMan) 10'!CK19=Reference!$A$8,'Bid Tab (F&B Ops and CatMan) 10'!CG19,IF('Bid Tab (F&B Ops and CatMan) 10'!CQ19=Reference!$A$8,'Bid Tab (F&B Ops and CatMan) 10'!CM19,0)))))))))) -> 0 | Y19: =IFERROR(IF(Reference!$A$8=HLOOKUP(Reference!$A$8,'Bid Tab (F&B Ops and CatMan) 10'!AJ19:CQ19,1,0),TRUE,FALSE),FALSE) -> FALSE | Z19: =MIN(IF(AO19=Reference!$A$10,100000000,AK19),IF(AU19=Reference!$A$10,100000000,AQ19),IF(BA19=Reference!$A$10,100000000,AW19),IF(BG19=Reference!$A$10,100000000,BC19),IF(BM19=Reference!$A$10,100000000,BI19),IF(BS19=Reference!$A$10,100000000,BO19),IF(BY19=Reference!$A$10,100000000,BU19),IF(CE19=Reference!$A$10,100000000,CA19),IF(CK19=Reference!$A$10,100000000,CG19),IF(CQ19=Reference!$A$10,100000000,CM19)) -> 0 | AA19: =IF(X19>0,X19*D19,Z19*D19) -> 0 | AB19: =IF(Reference!A26>0,Reference!A26,MAX(IF(TODAY()-H19<365,IF(G19>=N19,G19,P19),P19),G19)) -> 0 | AC19: =IF(AE19>0,AB19*$D19,O19) -> 0 | AD19: =IF(N19>$AB19,0,(($AB19-N19))) -> 0 | AE19: =IF(N19>$AB19,0,(($AB19-N19)*$D19)) -> 0 | AF19: =IF(AND((AD19=0),(F19=M19),(G19=N19),(TODAY()-H19<365)),"PRICE EXTENSION",IF(AND(G19=AB19,G19>0),"LAST SYSTEM PRICE",IF(AB19>0,"INITIAL LOWEST BID"," "))) | AG19: =IF(G19>0,G19-Z19,0) -> 0 | AH19: =AG19*D19 -> 0 | AI19: =IFERROR((G19-Z19)/G19,0) -> 0 | AL19: =IFERROR(AK19*$D19,0) -> 0 | AM19: =IFERROR(($G19-AK19)/$G19,0) -> 0 | AR19: =IFERROR(AQ19*$D19,0) -> 0 | AS19: =IFERROR(($G19-AQ19)/$G19,0) -> 0 | AX19: =IFERROR(AW19*$D19,0) -> 0 | AY19: =IFERROR(($G19-AW19)/$G19,0) -> 0 | BD19: =IFERROR(BC19*$D19,0) -> 0 | BE19: =IFERROR(($G19-BC19)/$G19,0) -> 0 | BJ19: =IFERROR(BI19*$D19,0) -> 0 | BK19: =IFERROR(($G19-BI19)/$G19,0) -> 0 | BP19: =IFERROR(BO19*$D19,0) -> 0 | BQ19: =IFERROR(($G19-BO19)/$G19,0) -> 0 | BV19: =IFERROR(BU19*$D19,0) -> 0 | BW19: =IFERROR(($G19-BU19)/$G19,0) -> 0 | CB19: =IFERROR(CA19*$D19,0) -> 0 | CC19: =IFERROR(($G19-CA19)/$G19,0) -> 0 | CH19: =IFERROR(CG19*$D19,0) -> 0 | CI19: =IFERROR(($G19-CG19)/$G19,0) -> 0 | CN19: =IFERROR(CM19*$D19,0) -> 0 | CO19: =IFERROR(($G19-CM19)/$G19,0) -> 0
A20: 10 | I20: =G20*D20 -> 0 | L20: =IFERROR((J20-N20)/J20,0) -> 0 | M20: =IF(N20>0,IF(N20=AK20,$AJ$9,IF(N20=AQ20,$AP$9,IF(N20=AW20,$AV$9,IF(N20=BC20,$BB$9,IF(N20=BI20,$BH$9,IF(N20=BO20,$BN$9,IF(N20=BU20,$BT$9,IF(N20=CA20,$BZ$9,IF(N20=CG20,$CF$9,IF(N20=CM20,$CL$9,"")))))))))),"") | N20: =IF(X20>0,X20,Z20) -> 0 | O20: =IFERROR(N20*D20,"") -> 0 | P20: =MIN(IF($AO20=Reference!$A$10,100000000,AJ20),IF($AU20=Reference!$A$10,100000000,AP20),IF($BA20=Reference!$A$10,100000000,AV20),IF($BG20=Reference!$A$10,100000000,BB20),IF($BM20=Reference!$A$10,100000000,BH20),IF($BS20=Reference!$A$10,100000000,BN20),IF($BY20=Reference!$A$10,100000000,BT20),IF($CE20=Reference!$A$10,100000000,BZ20),IF($CK20=Reference!$A$10,100000000,CF20),IF($CQ20=Reference!$A$10,100000000,CL20)) -> 0 | Q20: =W20=F20 -> FALSE | R20: =COUNT(BC20,AK20,AQ20,AW20,BI20,BO20,BU20,CA20,CG20,CM20) -> 0 | S20: =MIN(AK20,AQ20,AW20,BC20,BI20,BO20,BU20,CA20,CG20,CM20)=N20 -> TRUE | T20: =IFERROR(AVERAGE(AK20,AQ20,AW20,BC20,BI20,BO20,BU20,CA20,CG20,CM20),"") | U20: =IFERROR(((G20-T20)/G20),"") | V20: =$Z20=$N20 -> TRUE | W20: =IF(Z20=AK20,$AJ$9,IF(Z20=AQ20,$AP$9,IF(Z20=AW20,$AV$9,IF(Z20=BC20,$BB$9,IF(Z20=BI20,$BH$9,IF(Z20=BO20,$BN$9,IF(Z20=BU20,$BT$9,IF(Z20=CA20,$BZ$9,IF(Z20=CG20,$CF$9,IF(Z20=CM20,$CL$9,"")))))))))) -> VENDOR 1 | X20: =IF(AO20=Reference!$A$8,'Bid Tab (F&B Ops and CatMan) 10'!AK20,IF('Bid Tab (F&B Ops and CatMan) 10'!AU20=Reference!$A$8,'Bid Tab (F&B Ops and CatMan) 10'!AQ20,IF('Bid Tab (F&B Ops and CatMan) 10'!BA20=Reference!$A$8,'Bid Tab (F&B Ops and CatMan) 10'!AW20,IF('Bid Tab (F&B Ops and CatMan) 10'!BG20=Reference!$A$8,'Bid Tab (F&B Ops and CatMan) 10'!BC20,IF('Bid Tab (F&B Ops and CatMan) 10'!BM20=Reference!$A$8,'Bid Tab (F&B Ops and CatMan) 10'!BI20,IF('Bid Tab (F&B Ops and CatMan) 10'!BS20=Reference!$A$8,'Bid Tab (F&B Ops and CatMan) 10'!BO20,IF('Bid Tab (F&B Ops and CatMan) 10'!BY20=Reference!$A$8,'Bid Tab (F&B Ops and CatMan) 10'!BU20,IF('Bid Tab (F&B Ops and CatMan) 10'!CE20=Reference!$A$8,'Bid Tab (F&B Ops and CatMan) 10'!CA20,IF('Bid Tab (F&B Ops and CatMan) 10'!CK20=Reference!$A$8,'Bid Tab (F&B Ops and CatMan) 10'!CG20,IF('Bid Tab (F&B Ops and CatMan) 10'!CQ20=Reference!$A$8,'Bid Tab (F&B Ops and CatMan) 10'!CM20,0)))))))))) -> 0 | Y20: =IFERROR(IF(Reference!$A$8=HLOOKUP(Reference!$A$8,'Bid Tab (F&B Ops and CatMan) 10'!AJ20:CQ20,1,0),TRUE,FALSE),FALSE) -> FALSE | Z20: =MIN(IF(AO20=Reference!$A$10,100000000,AK20),IF(AU20=Reference!$A$10,100000000,AQ20),IF(BA20=Reference!$A$10,100000000,AW20),IF(BG20=Reference!$A$10,100000000,BC20),IF(BM20=Reference!$A$10,100000000,BI20),IF(BS20=Reference!$A$10,100000000,BO20),IF(BY20=Reference!$A$10,100000000,BU20),IF(CE20=Reference!$A$10,100000000,CA20),IF(CK20=Reference!$A$10,100000000,CG20),IF(CQ20=Reference!$A$10,100000000,CM20)) -> 0 | AA20: =IF(X20>0,X20*D20,Z20*D20) -> 0 | AB20: =IF(Reference!A27>0,Reference!A27,MAX(IF(TODAY()-H20<365,IF(G20>=N20,G20,P20),P20),G20)) -> 0 | AC20: =IF(AE20>0,AB20*$D20,O20) -> 0 | AD20: =IF(N20>$AB20,0,(($AB20-N20))) -> 0 | AE20: =IF(N20>$AB20,0,(($AB20-N20)*$D20)) -> 0 | AF20: =IF(AND((AD20=0),(F20=M20),(G20=N20),(TODAY()-H20<365)),"PRICE EXTENSION",IF(AND(G20=AB20,G20>0),"LAST SYSTEM PRICE",IF(AB20>0,"INITIAL LOWEST BID"," "))) | AG20: =IF(G20>0,G20-Z20,0) -> 0 | AH20: =AG20*D20 -> 0 | AI20: =IFERROR((G20-Z20)/G20,0) -> 0 | AL20: =IFERROR(AK20*$D20,0) -> 0 | AM20: =IFERROR(($G20-AK20)/$G20,0) -> 0 | AR20: =IFERROR(AQ20*$D20,0) -> 0 | AS20: =IFERROR(($G20-AQ20)/$G20,0) -> 0 | AX20: =IFERROR(AW20*$D20,0) -> 0 | AY20: =IFERROR(($G20-AW20)/$G20,0) -> 0 | BD20: =IFERROR(BC20*$D20,0) -> 0 | BE20: =IFERROR(($G20-BC20)/$G20,0) -> 0 | BJ20: =IFERROR(BI20*$D20,0) -> 0 | BK20: =IFERROR(($G20-BI20)/$G20,0) -> 0 | BP20: =IFERROR(BO20*$D20,0) -> 0 | BQ20: =IFERROR(($G20-BO20)/$G20,0) -> 0 | BV20: =IFERROR(BU20*$D20,0) -> 0 | BW20: =IFERROR(($G20-BU20)/$G20,0) -> 0 | CB20: =IFERROR(CA20*$D20,0) -> 0 | CC20: =IFERROR(($G20-CA20)/$G20,0) -> 0 | CH20: =IFERROR(CG20*$D20,0) -> 0 | CI20: =IFERROR(($G20-CG20)/$G20,0) -> 0 | CN20: =IFERROR(CM20*$D20,0) -> 0 | CO20: =IFERROR(($G20-CM20)/$G20,0) -> 0
A21: 11 | I21: =G21*D21 -> 0 | L21: =IFERROR((J21-N21)/J21,0) -> 0 | M21: =IF(N21>0,IF(N21=AK21,$AJ$9,IF(N21=AQ21,$AP$9,IF(N21=AW21,$AV$9,IF(N21=BC21,$BB$9,IF(N21=BI21,$BH$9,IF(N21=BO21,$BN$9,IF(N21=BU21,$BT$9,IF(N21=CA21,$BZ$9,IF(N21=CG21,$CF$9,IF(N21=CM21,$CL$9,"")))))))))),"") | N21: =IF(X21>0,X21,Z21) -> 0 | O21: =IFERROR(N21*D21,"") -> 0 | P21: =MIN(IF($AO21=Reference!$A$10,100000000,AJ21),IF($AU21=Reference!$A$10,100000000,AP21),IF($BA21=Reference!$A$10,100000000,AV21),IF($BG21=Reference!$A$10,100000000,BB21),IF($BM21=Reference!$A$10,100000000,BH21),IF($BS21=Reference!$A$10,100000000,BN21),IF($BY21=Reference!$A$10,100000000,BT21),IF($CE21=Reference!$A$10,100000000,BZ21),IF($CK21=Reference!$A$10,100000000,CF21),IF($CQ21=Reference!$A$10,100000000,CL21)) -> 0 | Q21: =W21=F21 -> FALSE | R21: =COUNT(BC21,AK21,AQ21,AW21,BI21,BO21,BU21,CA21,CG21,CM21) -> 0 | S21: =MIN(AK21,AQ21,AW21,BC21,BI21,BO21,BU21,CA21,CG21,CM21)=N21 -> TRUE | T21: =IFERROR(AVERAGE(AK21,AQ21,AW21,BC21,BI21,BO21,BU21,CA21,CG21,CM21),"") | U21: =IFERROR(((G21-T21)/G21),"") | V21: =$Z21=$N21 -> TRUE | W21: =IF(Z21=AK21,$AJ$9,IF(Z21=AQ21,$AP$9,IF(Z21=AW21,$AV$9,IF(Z21=BC21,$BB$9,IF(Z21=BI21,$BH$9,IF(Z21=BO21,$BN$9,IF(Z21=BU21,$BT$9,IF(Z21=CA21,$BZ$9,IF(Z21=CG21,$CF$9,IF(Z21=CM21,$CL$9,"")))))))))) -> VENDOR 1 | X21: =IF(AO21=Reference!$A$8,'Bid Tab (F&B Ops and CatMan) 10'!AK21,IF('Bid Tab (F&B Ops and CatMan) 10'!AU21=Reference!$A$8,'Bid Tab (F&B Ops and CatMan) 10'!AQ21,IF('Bid Tab (F&B Ops and CatMan) 10'!BA21=Reference!$A$8,'Bid Tab (F&B Ops and CatMan) 10'!AW21,IF('Bid Tab (F&B Ops and CatMan) 10'!BG21=Reference!$A$8,'Bid Tab (F&B Ops and CatMan) 10'!BC21,IF('Bid Tab (F&B Ops and CatMan) 10'!BM21=Reference!$A$8,'Bid Tab (F&B Ops and CatMan) 10'!BI21,IF('Bid Tab (F&B Ops and CatMan) 10'!BS21=Reference!$A$8,'Bid Tab (F&B Ops and CatMan) 10'!BO21,IF('Bid Tab (F&B Ops and CatMan) 10'!BY21=Reference!$A$8,'Bid Tab (F&B Ops and CatMan) 10'!BU21,IF('Bid Tab (F&B Ops and CatMan) 10'!CE21=Reference!$A$8,'Bid Tab (F&B Ops and CatMan) 10'!CA21,IF('Bid Tab (F&B Ops and CatMan) 10'!CK21=Reference!$A$8,'Bid Tab (F&B Ops and CatMan) 10'!CG21,IF('Bid Tab (F&B Ops and CatMan) 10'!CQ21=Reference!$A$8,'Bid Tab (F&B Ops and CatMan) 10'!CM21,0)))))))))) -> 0 | Y21: =IFERROR(IF(Reference!$A$8=HLOOKUP(Reference!$A$8,'Bid Tab (F&B Ops and CatMan) 10'!AJ21:CQ21,1,0),TRUE,FALSE),FALSE) -> FALSE | Z21: =MIN(IF(AO21=Reference!$A$10,100000000,AK21),IF(AU21=Reference!$A$10,100000000,AQ21),IF(BA21=Reference!$A$10,100000000,AW21),IF(BG21=Reference!$A$10,100000000,BC21),IF(BM21=Reference!$A$10,100000000,BI21),IF(BS21=Reference!$A$10,100000000,BO21),IF(BY21=Reference!$A$10,100000000,BU21),IF(CE21=Reference!$A$10,100000000,CA21),IF(CK21=Reference!$A$10,100000000,CG21),IF(CQ21=Reference!$A$10,100000000,CM21)) -> 0 | AA21: =IF(X21>0,X21*D21,Z21*D21) -> 0 | AB21: =IF(Reference!A28>0,Reference!A28,MAX(IF(TODAY()-H21<365,IF(G21>=N21,G21,P21),P21),G21)) -> 0 | AC21: =IF(AE21>0,AB21*$D21,O21) -> 0 | AD21: =IF(N21>$AB21,0,(($AB21-N21))) -> 0 | AE21: =IF(N21>$AB21,0,(($AB21-N21)*$D21)) -> 0 | AF21: =IF(AND((AD21=0),(F21=M21),(G21=N21),(TODAY()-H21<365)),"PRICE EXTENSION",IF(AND(G21=AB21,G21>0),"LAST SYSTEM PRICE",IF(AB21>0,"INITIAL LOWEST BID"," "))) | AG21: =IF(G21>0,G21-Z21,0) -> 0 | AH21: =AG21*D21 -> 0 | AI21: =IFERROR((G21-Z21)/G21,0) -> 0 | AL21: =IFERROR(AK21*$D21,0) -> 0 | AM21: =IFERROR(($G21-AK21)/$G21,0) -> 0 | AR21: =IFERROR(AQ21*$D21,0) -> 0 | AS21: =IFERROR(($G21-AQ21)/$G21,0) -> 0 | AX21: =IFERROR(AW21*$D21,0) -> 0 | AY21: =IFERROR(($G21-AW21)/$G21,0) -> 0 | BD21: =IFERROR(BC21*$D21,0) -> 0 | BE21: =IFERROR(($G21-BC21)/$G21,0) -> 0 | BJ21: =IFERROR(BI21*$D21,0) -> 0 | BK21: =IFERROR(($G21-BI21)/$G21,0) -> 0 | BP21: =IFERROR(BO21*$D21,0) -> 0 | BQ21: =IFERROR(($G21-BO21)/$G21,0) -> 0 | BV21: =IFERROR(BU21*$D21,0) -> 0 | BW21: =IFERROR(($G21-BU21)/$G21,0) -> 0 | CB21: =IFERROR(CA21*$D21,0) -> 0 | CC21: =IFERROR(($G21-CA21)/$G21,0) -> 0 | CH21: =IFERROR(CG21*$D21,0) -> 0 | CI21: =IFERROR(($G21-CG21)/$G21,0) -> 0 | CN21: =IFERROR(CM21*$D21,0) -> 0 | CO21: =IFERROR(($G21-CM21)/$G21,0) -> 0
A22: 12 | I22: =G22*D22 -> 0 | L22: =IFERROR((J22-N22)/J22,0) -> 0 | M22: =IF(N22>0,IF(N22=AK22,$AJ$9,IF(N22=AQ22,$AP$9,IF(N22=AW22,$AV$9,IF(N22=BC22,$BB$9,IF(N22=BI22,$BH$9,IF(N22=BO22,$BN$9,IF(N22=BU22,$BT$9,IF(N22=CA22,$BZ$9,IF(N22=CG22,$CF$9,IF(N22=CM22,$CL$9,"")))))))))),"") | N22: =IF(X22>0,X22,Z22) -> 0 | O22: =IFERROR(N22*D22,"") -> 0 | P22: =MIN(IF($AO22=Reference!$A$10,100000000,AJ22),IF($AU22=Reference!$A$10,100000000,AP22),IF($BA22=Reference!$A$10,100000000,AV22),IF($BG22=Reference!$A$10,100000000,BB22),IF($BM22=Reference!$A$10,100000000,BH22),IF($BS22=Reference!$A$10,100000000,BN22),IF($BY22=Reference!$A$10,100000000,BT22),IF($CE22=Reference!$A$10,100000000,BZ22),IF($CK22=Reference!$A$10,100000000,CF22),IF($CQ22=Reference!$A$10,100000000,CL22)) -> 0 | Q22: =W22=F22 -> FALSE | R22: =COUNT(BC22,AK22,AQ22,AW22,BI22,BO22,BU22,CA22,CG22,CM22) -> 0 | S22: =MIN(AK22,AQ22,AW22,BC22,BI22,BO22,BU22,CA22,CG22,CM22)=N22 -> TRUE | T22: =IFERROR(AVERAGE(AK22,AQ22,AW22,BC22,BI22,BO22,BU22,CA22,CG22,CM22),"") | U22: =IFERROR(((G22-T22)/G22),"") | V22: =$Z22=$N22 -> TRUE | W22: =IF(Z22=AK22,$AJ$9,IF(Z22=AQ22,$AP$9,IF(Z22=AW22,$AV$9,IF(Z22=BC22,$BB$9,IF(Z22=BI22,$BH$9,IF(Z22=BO22,$BN$9,IF(Z22=BU22,$BT$9,IF(Z22=CA22,$BZ$9,IF(Z22=CG22,$CF$9,IF(Z22=CM22,$CL$9,"")))))))))) -> VENDOR 1 | X22: =IF(AO22=Reference!$A$8,'Bid Tab (F&B Ops and CatMan) 10'!AK22,IF('Bid Tab (F&B Ops and CatMan) 10'!AU22=Reference!$A$8,'Bid Tab (F&B Ops and CatMan) 10'!AQ22,IF('Bid Tab (F&B Ops and CatMan) 10'!BA22=Reference!$A$8,'Bid Tab (F&B Ops and CatMan) 10'!AW22,IF('Bid Tab (F&B Ops and CatMan) 10'!BG22=Reference!$A$8,'Bid Tab (F&B Ops and CatMan) 10'!BC22,IF('Bid Tab (F&B Ops and CatMan) 10'!BM22=Reference!$A$8,'Bid Tab (F&B Ops and CatMan) 10'!BI22,IF('Bid Tab (F&B Ops and CatMan) 10'!BS22=Reference!$A$8,'Bid Tab (F&B Ops and CatMan) 10'!BO22,IF('Bid Tab (F&B Ops and CatMan) 10'!BY22=Reference!$A$8,'Bid Tab (F&B Ops and CatMan) 10'!BU22,IF('Bid Tab (F&B Ops and CatMan) 10'!CE22=Reference!$A$8,'Bid Tab (F&B Ops and CatMan) 10'!CA22,IF('Bid Tab (F&B Ops and CatMan) 10'!CK22=Reference!$A$8,'Bid Tab (F&B Ops and CatMan) 10'!CG22,IF('Bid Tab (F&B Ops and CatMan) 10'!CQ22=Reference!$A$8,'Bid Tab (F&B Ops and CatMan) 10'!CM22,0)))))))))) -> 0 | Y22: =IFERROR(IF(Reference!$A$8=HLOOKUP(Reference!$A$8,'Bid Tab (F&B Ops and CatMan) 10'!AJ22:CQ22,1,0),TRUE,FALSE),FALSE) -> FALSE | Z22: =MIN(IF(AO22=Reference!$A$10,100000000,AK22),IF(AU22=Reference!$A$10,100000000,AQ22),IF(BA22=Reference!$A$10,100000000,AW22),IF(BG22=Reference!$A$10,100000000,BC22),IF(BM22=Reference!$A$10,100000000,BI22),IF(BS22=Reference!$A$10,100000000,BO22),IF(BY22=Reference!$A$10,100000000,BU22),IF(CE22=Reference!$A$10,100000000,CA22),IF(CK22=Reference!$A$10,100000000,CG22),IF(CQ22=Reference!$A$10,100000000,CM22)) -> 0 | AA22: =IF(X22>0,X22*D22,Z22*D22) -> 0 | AB22: =IF(Reference!A29>0,Reference!A29,MAX(IF(TODAY()-H22<365,IF(G22>=N22,G22,P22),P22),G22)) -> 0 | AC22: =IF(AE22>0,AB22*$D22,O22) -> 0 | AD22: =IF(N22>$AB22,0,(($AB22-N22))) -> 0 | AE22: =IF(N22>$AB22,0,(($AB22-N22)*$D22)) -> 0 | AF22: =IF(AND((AD22=0),(F22=M22),(G22=N22),(TODAY()-H22<365)),"PRICE EXTENSION",IF(AND(G22=AB22,G22>0),"LAST SYSTEM PRICE",IF(AB22>0,"INITIAL LOWEST BID"," "))) | AG22: =IF(G22>0,G22-Z22,0) -> 0 | AH22: =AG22*D22 -> 0 | AI22: =IFERROR((G22-Z22)/G22,0) -> 0 | AL22: =IFERROR(AK22*$D22,0) -> 0 | AM22: =IFERROR(($G22-AK22)/$G22,0) -> 0 | AR22: =IFERROR(AQ22*$D22,0) -> 0 | AS22: =IFERROR(($G22-AQ22)/$G22,0) -> 0 | AX22: =IFERROR(AW22*$D22,0) -> 0 | AY22: =IFERROR(($G22-AW22)/$G22,0) -> 0 | BD22: =IFERROR(BC22*$D22,0) -> 0 | BE22: =IFERROR(($G22-BC22)/$G22,0) -> 0 | BJ22: =IFERROR(BI22*$D22,0) -> 0 | BK22: =IFERROR(($G22-BI22)/$G22,0) -> 0 | BP22: =IFERROR(BO22*$D22,0) -> 0 | BQ22: =IFERROR(($G22-BO22)/$G22,0) -> 0 | BV22: =IFERROR(BU22*$D22,0) -> 0 | BW22: =IFERROR(($G22-BU22)/$G22,0) -> 0 | CB22: =IFERROR(CA22*$D22,0) -> 0 | CC22: =IFERROR(($G22-CA22)/$G22,0) -> 0 | CH22: =IFERROR(CG22*$D22,0) -> 0 | CI22: =IFERROR(($G22-CG22)/$G22,0) -> 0 | CN22: =IFERROR(CM22*$D22,0) -> 0 | CO22: =IFERROR(($G22-CM22)/$G22,0) -> 0
A23: 13 | I23: =G23*D23 -> 0 | L23: =IFERROR((J23-N23)/J23,0) -> 0 | M23: =IF(N23>0,IF(N23=AK23,$AJ$9,IF(N23=AQ23,$AP$9,IF(N23=AW23,$AV$9,IF(N23=BC23,$BB$9,IF(N23=BI23,$BH$9,IF(N23=BO23,$BN$9,IF(N23=BU23,$BT$9,IF(N23=CA23,$BZ$9,IF(N23=CG23,$CF$9,IF(N23=CM23,$CL$9,"")))))))))),"") | N23: =IF(X23>0,X23,Z23) -> 0 | O23: =IFERROR(N23*D23,"") -> 0 | P23: =MIN(IF($AO23=Reference!$A$10,100000000,AJ23),IF($AU23=Reference!$A$10,100000000,AP23),IF($BA23=Reference!$A$10,100000000,AV23),IF($BG23=Reference!$A$10,100000000,BB23),IF($BM23=Reference!$A$10,100000000,BH23),IF($BS23=Reference!$A$10,100000000,BN23),IF($BY23=Reference!$A$10,100000000,BT23),IF($CE23=Reference!$A$10,100000000,BZ23),IF($CK23=Reference!$A$10,100000000,CF23),IF($CQ23=Reference!$A$10,100000000,CL23)) -> 0 | Q23: =W23=F23 -> FALSE | R23: =COUNT(BC23,AK23,AQ23,AW23,BI23,BO23,BU23,CA23,CG23,CM23) -> 0 | S23: =MIN(AK23,AQ23,AW23,BC23,BI23,BO23,BU23,CA23,CG23,CM23)=N23 -> TRUE | T23: =IFERROR(AVERAGE(AK23,AQ23,AW23,BC23,BI23,BO23,BU23,CA23,CG23,CM23),"") | U23: =IFERROR(((G23-T23)/G23),"") | V23: =$Z23=$N23 -> TRUE | W23: =IF(Z23=AK23,$AJ$9,IF(Z23=AQ23,$AP$9,IF(Z23=AW23,$AV$9,IF(Z23=BC23,$BB$9,IF(Z23=BI23,$BH$9,IF(Z23=BO23,$BN$9,IF(Z23=BU23,$BT$9,IF(Z23=CA23,$BZ$9,IF(Z23=CG23,$CF$9,IF(Z23=CM23,$CL$9,"")))))))))) -> VENDOR 1 | X23: =IF(AO23=Reference!$A$8,'Bid Tab (F&B Ops and CatMan) 10'!AK23,IF('Bid Tab (F&B Ops and CatMan) 10'!AU23=Reference!$A$8,'Bid Tab (F&B Ops and CatMan) 10'!AQ23,IF('Bid Tab (F&B Ops and CatMan) 10'!BA23=Reference!$A$8,'Bid Tab (F&B Ops and CatMan) 10'!AW23,IF('Bid Tab (F&B Ops and CatMan) 10'!BG23=Reference!$A$8,'Bid Tab (F&B Ops and CatMan) 10'!BC23,IF('Bid Tab (F&B Ops and CatMan) 10'!BM23=Reference!$A$8,'Bid Tab (F&B Ops and CatMan) 10'!BI23,IF('Bid Tab (F&B Ops and CatMan) 10'!BS23=Reference!$A$8,'Bid Tab (F&B Ops and CatMan) 10'!BO23,IF('Bid Tab (F&B Ops and CatMan) 10'!BY23=Reference!$A$8,'Bid Tab (F&B Ops and CatMan) 10'!BU23,IF('Bid Tab (F&B Ops and CatMan) 10'!CE23=Reference!$A$8,'Bid Tab (F&B Ops and CatMan) 10'!CA23,IF('Bid Tab (F&B Ops and CatMan) 10'!CK23=Reference!$A$8,'Bid Tab (F&B Ops and CatMan) 10'!CG23,IF('Bid Tab (F&B Ops and CatMan) 10'!CQ23=Reference!$A$8,'Bid Tab (F&B Ops and CatMan) 10'!CM23,0)))))))))) -> 0 | Y23: =IFERROR(IF(Reference!$A$8=HLOOKUP(Reference!$A$8,'Bid Tab (F&B Ops and CatMan) 10'!AJ23:CQ23,1,0),TRUE,FALSE),FALSE) -> FALSE | Z23: =MIN(IF(AO23=Reference!$A$10,100000000,AK23),IF(AU23=Reference!$A$10,100000000,AQ23),IF(BA23=Reference!$A$10,100000000,AW23),IF(BG23=Reference!$A$10,100000000,BC23),IF(BM23=Reference!$A$10,100000000,BI23),IF(BS23=Reference!$A$10,100000000,BO23),IF(BY23=Reference!$A$10,100000000,BU23),IF(CE23=Reference!$A$10,100000000,CA23),IF(CK23=Reference!$A$10,100000000,CG23),IF(CQ23=Reference!$A$10,100000000,CM23)) -> 0 | AA23: =IF(X23>0,X23*D23,Z23*D23) -> 0 | AB23: =IF(Reference!A30>0,Reference!A30,MAX(IF(TODAY()-H23<365,IF(G23>=N23,G23,P23),P23),G23)) -> 0 | AC23: =IF(AE23>0,AB23*$D23,O23) -> 0 | AD23: =IF(N23>$AB23,0,(($AB23-N23))) -> 0 | AE23: =IF(N23>$AB23,0,(($AB23-N23)*$D23)) -> 0 | AF23: =IF(AND((AD23=0),(F23=M23),(G23=N23),(TODAY()-H23<365)),"PRICE EXTENSION",IF(AND(G23=AB23,G23>0),"LAST SYSTEM PRICE",IF(AB23>0,"INITIAL LOWEST BID"," "))) | AG23: =IF(G23>0,G23-Z23,0) -> 0 | AH23: =AG23*D23 -> 0 | AI23: =IFERROR((G23-Z23)/G23,0) -> 0 | AL23: =IFERROR(AK23*$D23,0) -> 0 | AM23: =IFERROR(($G23-AK23)/$G23,0) -> 0 | AR23: =IFERROR(AQ23*$D23,0) -> 0 | AS23: =IFERROR(($G23-AQ23)/$G23,0) -> 0 | AX23: =IFERROR(AW23*$D23,0) -> 0 | AY23: =IFERROR(($G23-AW23)/$G23,0) -> 0 | BD23: =IFERROR(BC23*$D23,0) -> 0 | BE23: =IFERROR(($G23-BC23)/$G23,0) -> 0 | BJ23: =IFERROR(BI23*$D23,0) -> 0 | BK23: =IFERROR(($G23-BI23)/$G23,0) -> 0 | BP23: =IFERROR(BO23*$D23,0) -> 0 | BQ23: =IFERROR(($G23-BO23)/$G23,0) -> 0 | BV23: =IFERROR(BU23*$D23,0) -> 0 | BW23: =IFERROR(($G23-BU23)/$G23,0) -> 0 | CB23: =IFERROR(CA23*$D23,0) -> 0 | CC23: =IFERROR(($G23-CA23)/$G23,0) -> 0 | CH23: =IFERROR(CG23*$D23,0) -> 0 | CI23: =IFERROR(($G23-CG23)/$G23,0) -> 0 | CN23: =IFERROR(CM23*$D23,0) -> 0 | CO23: =IFERROR(($G23-CM23)/$G23,0) -> 0
